<?xml version="1.0" ?>
<!-- =================================================================================== -->
<!-- |    This document was autogenerated by xacro from ambula.urdf.xacro              | -->
<!-- |    EDITING THIS FILE BY HAND IS NOT RECOMMENDED                                 | -->
<!-- =================================================================================== -->
<robot name="ambula_bot">
  <gazebo>
    <plugin filename="gz-sim-joint-position-controller-system" name="gz::sim::systems::JointPositionController">
      <joint_name>left_hip_joint</joint_name>
      <initial_position>-2.0</initial_position>
      <topic>left_hip_position_cmd</topic>
      <p_gain>250.0</p_gain>
      <i_gain>50.0</i_gain>
      <d_gain>0.01</d_gain>
    </plugin>
    <plugin filename="gz-sim-joint-position-controller-system" name="gz::sim::systems::JointPositionController">
      <joint_name>right_hip_joint</joint_name>
      <initial_position>-2.0</initial_position>
      <topic>right_hip_position_cmd</topic>
      <p_gain>250.0</p_gain>
      <i_gain>50.0</i_gain>
      <d_gain>0.01</d_gain>
    </plugin>
    <plugin filename="gz-sim-joint-position-controller-system" name="gz::sim::systems::JointPositionController">
      <joint_name>left_knee_joint</joint_name>
      <initial_position>-2.85</initial_position>
      <topic>left_knee_position_cmd</topic>
      <p_gain>250.0</p_gain>
      <i_gain>50.0</i_gain>
      <d_gain>0.01</d_gain>
    </plugin>
    <plugin filename="gz-sim-joint-position-controller-system" name="gz::sim::systems::JointPositionController">
      <joint_name>right_knee_joint</joint_name>
      <initial_position>-2.85</initial_position>
      <topic>right_knee_position_cmd</topic>
      <p_gain>250.0</p_gain>
      <i_gain>50.0</i_gain>
      <d_gain>0.01</d_gain>
    </plugin>
    <plugin filename="gz-sim-joint-controller-system" name="gz::sim::systems::JointController">
      <joint_name>left_wheel_joint</joint_name>
      <topic>left_wheel_velocity_cmd</topic>
      <p_gain>40.0</p_gain>
      <i_gain>1.0</i_gain>
      <d_gain>0.01</d_gain>
    </plugin>
    <plugin filename="gz-sim-joint-controller-system" name="gz::sim::systems::JointController">
      <joint_name>right_wheel_joint</joint_name>
      <topic>right_wheel_velocity_cmd</topic>
      <p_gain>40.0</p_gain>
      <i_gain>1.0</i_gain>
      <d_gain>0.01</d_gain>
    </plugin>
    <plugin filename="gz-sim-joint-position-controller-system" name="gz::sim::systems::JointPositionController">
      <joint_name>pillar1_to_base</joint_name>
      <initial_position>0.0</initial_position>
      <topic>pillar1_position_cmd</topic>
      <p_gain>40.0</p_gain>
      <i_gain>1.0</i_gain>
      <d_gain>0.01</d_gain>
    </plugin>
    <plugin filename="gz-sim-joint-position-controller-system" name="gz::sim::systems::JointPositionController">
      <joint_name>pillar2_to_base</joint_name>
      <initial_position>0.0</initial_position>
      <topic>pillar2_position_cmd</topic>
      <p_gain>40.0</p_gain>
      <i_gain>1.0</i_gain>
      <d_gain>0.01</d_gain>
    </plugin>
    <plugin filename="gz-sim-joint-state-publisher-system" name="gz::sim::systems::JointStatePublisher">
      <topic>joint_states</topic>
      <topic>left_hip_joint</topic>
      <topic>right_hip_joint</topic>
      <topic>left_knee_joint</topic>
      <topic>right_knee_joint</topic>
      <topic>left_wheel_joint</topic>
      <topic>right_wheel_joint</topic>
    </plugin>
  </gazebo>
  <!-- <link name="world" /> -->
  <link name="base_footprint"/>
  <link name="base_link">
    <visual>
      <origin rpy="0 0 0" xyz="0 0 0.15"/>
      <geometry>
        <box size="0.3 0.3 0.3"/>
      </geometry>
      <material name="orange">
        <color rgba="1.0 0.3 0.0 1.0"/>
      </material>
    </visual>
    <collision>
      <origin rpy="0 0 0" xyz="0 0 0.15"/>
      <geometry>
        <box size="0.3 0.3 0.3"/>
      </geometry>
    </collision>
    <inertial>
      <origin rpy="0 0 0" xyz="0 0 0.15"/>
      <mass value="7.0"/>
      <inertia ixx="0.10499999999999998" ixy="0.0" ixz="0.0" iyy="0.10499999999999998" iyz="0.0" izz="0.10499999999999998"/>
    </inertial>
  </link>
  <gazebo reference="base_link">
    <visual>
      <material>
        <ambient>0.8392 0.6314 0.0 1.0</ambient>
        <diffuse>0.8392 0.6314 0.0 1.0</diffuse>
        <specular>0.99 0.99 0.99 1.0</specular>
        <emissive>0.0 0.0 0.0 0.0</emissive>
      </material>
    </visual>
  </gazebo>
  <!-- <joint name="world_to_base" type="fixed">
            <origin rpy="0 0 0" xyz="0 0 1.0" />
            <parent link="world" />
            <child link="base_link" />
        </joint> -->
  <joint name="base_to_footprint" type="fixed">
    <parent link="base_footprint"/>
    <child link="base_link"/>
    <origin rpy="0 0 0" xyz="0 0 0.5"/>
  </joint>
  <link name="left_hip_link">
    <visual>
      <origin rpy="0 0 0" xyz="0 0 0.14"/>
      <geometry>
        <box size="0.1 0.1 0.28"/>
      </geometry>
      <material name="orange">
        <color rgba="1.0 0.3 0.0 1.0"/>
      </material>
    </visual>
    <collision>
      <origin rpy="0 0 0" xyz="0 0 0.14"/>
      <geometry>
        <box size="0.1 0.1 0.28"/>
      </geometry>
    </collision>
    <inertial>
      <origin rpy="0 0 0" xyz="0 0 0.14"/>
      <mass value="1.0"/>
      <inertia ixx="0.007366666666666667" ixy="0.0" ixz="0.0" iyy="0.007366666666666667" iyz="0.0" izz="0.001666666666666667"/>
    </inertial>
  </link>
  <gazebo reference="base_link">
    <visual>
      <material>
        <ambient>0.8392 0.6314 0.0 1.0</ambient>
        <diffuse>0.8392 0.6314 0.0 1.0</diffuse>
        <specular>0.99 0.99 0.99 1.0</specular>
        <emissive>0.0 0.0 0.0 0.0</emissive>
      </material>
    </visual>
  </gazebo>
  <joint name="left_hip_joint" type="revolute">
    <axis xyz="0 1 0"/>
    <origin xyz="0.0 0.2 0.1"/>
    <parent link="base_link"/>
    <child link="left_hip_link"/>
    <limit effort="1000" lower="-3.141592653589793" upper="0.0" velocity="10"/>
    <dynamics damping="5.0" friction="3.0"/>
  </joint>
  <link name="right_hip_link">
    <visual>
      <origin rpy="0 0 0" xyz="0 0 0.14"/>
      <geometry>
        <box size="0.1 0.1 0.28"/>
      </geometry>
      <material name="orange">
        <color rgba="1.0 0.3 0.0 1.0"/>
      </material>
    </visual>
    <collision>
      <origin rpy="0 0 0" xyz="0 0 0.14"/>
      <geometry>
        <box size="0.1 0.1 0.28"/>
      </geometry>
    </collision>
    <inertial>
      <origin rpy="0 0 0" xyz="0 0 0.14"/>
      <mass value="1.0"/>
      <inertia ixx="0.007366666666666667" ixy="0.0" ixz="0.0" iyy="0.007366666666666667" iyz="0.0" izz="0.001666666666666667"/>
    </inertial>
  </link>
  <gazebo reference="base_link">
    <visual>
      <material>
        <ambient>0.8392 0.6314 0.0 1.0</ambient>
        <diffuse>0.8392 0.6314 0.0 1.0</diffuse>
        <specular>0.99 0.99 0.99 1.0</specular>
        <emissive>0.0 0.0 0.0 0.0</emissive>
      </material>
    </visual>
  </gazebo>
  <joint name="right_hip_joint" type="revolute">
    <axis xyz="0 1 0"/>
    <origin xyz="0.0 -0.2 0.1"/>
    <parent link="base_link"/>
    <child link="right_hip_link"/>
    <limit effort="1000" lower="-3.141592653589793" upper="0.0" velocity="10"/>
    <dynamics damping="5.0" friction="3.0"/>
  </joint>
  <link name="left_knee_link">
    <visual>
      <origin rpy="0 0 0" xyz="0 0 0.15"/>
      <geometry>
        <box size="0.1 0.1 0.3"/>
      </geometry>
      <material name="orange">
        <color rgba="1.0 0.3 0.0 1.0"/>
      </material>
    </visual>
    <collision>
      <origin rpy="0 0 0" xyz="0 0 0.15"/>
      <geometry>
        <box size="0.1 0.1 0.3"/>
      </geometry>
    </collision>
    <inertial>
      <origin rpy="0 0 0" xyz="0 0 0.15"/>
      <mass value="1.0"/>
      <inertia ixx="0.008333333333333333" ixy="0.0" ixz="0.0" iyy="0.008333333333333333" iyz="0.0" izz="0.001666666666666667"/>
    </inertial>
  </link>
  <gazebo reference="base_link">
    <visual>
      <material>
        <ambient>0.8392 0.6314 0.0 1.0</ambient>
        <diffuse>0.8392 0.6314 0.0 1.0</diffuse>
        <specular>0.99 0.99 0.99 1.0</specular>
        <emissive>0.0 0.0 0.0 0.0</emissive>
      </material>
    </visual>
  </gazebo>
  <joint name="left_knee_joint" type="revolute">
    <axis xyz="0 1 0"/>
    <origin xyz="0.0 0.0 0.28"/>
    <parent link="left_hip_link"/>
    <child link="left_knee_link"/>
    <limit effort="1000" lower="-3.141592653589793" upper="0.0" velocity="10"/>
    <dynamics damping="5.0" friction="3.0"/>
  </joint>
  <link name="right_knee_link">
    <visual>
      <origin rpy="0 0 0" xyz="0 0 0.15"/>
      <geometry>
        <box size="0.1 0.1 0.3"/>
      </geometry>
      <material name="orange">
        <color rgba="1.0 0.3 0.0 1.0"/>
      </material>
    </visual>
    <collision>
      <origin rpy="0 0 0" xyz="0 0 0.15"/>
      <geometry>
        <box size="0.1 0.1 0.3"/>
      </geometry>
    </collision>
    <inertial>
      <origin rpy="0 0 0" xyz="0 0 0.15"/>
      <mass value="1.0"/>
      <inertia ixx="0.008333333333333333" ixy="0.0" ixz="0.0" iyy="0.008333333333333333" iyz="0.0" izz="0.001666666666666667"/>
    </inertial>
  </link>
  <gazebo reference="base_link">
    <visual>
      <material>
        <ambient>0.8392 0.6314 0.0 1.0</ambient>
        <diffuse>0.8392 0.6314 0.0 1.0</diffuse>
        <specular>0.99 0.99 0.99 1.0</specular>
        <emissive>0.0 0.0 0.0 0.0</emissive>
      </material>
    </visual>
  </gazebo>
  <joint name="right_knee_joint" type="revolute">
    <axis xyz="0 1 0"/>
    <origin xyz="0.0 0.0 0.28"/>
    <parent link="right_hip_link"/>
    <child link="right_knee_link"/>
    <limit effort="1000" lower="-3.141592653589793" upper="0.0" velocity="10"/>
    <dynamics damping="5.0" friction="3.0"/>
  </joint>
  <link name="left_wheel_link">
    <visual>
      <origin rpy="1.5707963267948966 0 0" xyz="0 0 0"/>
      <geometry>
        <cylinder length="0.04" radius="0.075"/>
      </geometry>
      <material name="blue">
        <color rgba="0.1764 0.4588 0.8509 1.0"/>
      </material>
    </visual>
    <collision>
      <origin rpy="1.5707963267948966 0 0" xyz="0 0 0"/>
      <geometry>
        <cylinder length="0.04" radius="0.075"/>
      </geometry>
    </collision>
    <inertial>
      <origin rpy="0 0 0" xyz="0 0 0"/>
      <mass value="2.0"/>
      <inertia ixx="0.0045" ixy="0" ixz="0" iyy="0.0045" iyz="0" izz="0.0045"/>
    </inertial>
  </link>
  <gazebo reference="left_wheel_link">
    <mu1>0.01</mu1>
    <mu2>0.01</mu2>
  </gazebo>
  <gazebo reference="left_wheel_link">
    <visual>
      <material>
        <ambient>0.1764 0.4588 0.8509 1.0</ambient>
        <diffuse>0.1764 0.4588 0.8509 1.0</diffuse>
        <specular>0.1764 0.4588 0.8509 1.0</specular>
        <emissive>0.0 0.0 0.0 0.0</emissive>
      </material>
    </visual>
  </gazebo>
  <joint name="left_wheel_joint" type="continuous">
    <axis xyz="0 1 0"/>
    <parent link="left_knee_link"/>
    <child link="left_wheel_link"/>
    <origin rpy="0 0 0" xyz="0.0 0.0 0.3"/>
    <dynamics damping="0.01" friction="0.0"/>
  </joint>
  <link name="right_wheel_link">
    <visual>
      <origin rpy="1.5707963267948966 0 0" xyz="0 0 0"/>
      <geometry>
        <cylinder length="0.04" radius="0.075"/>
      </geometry>
      <material name="blue">
        <color rgba="0.1764 0.4588 0.8509 1.0"/>
      </material>
    </visual>
    <collision>
      <origin rpy="1.5707963267948966 0 0" xyz="0 0 0"/>
      <geometry>
        <cylinder length="0.04" radius="0.075"/>
      </geometry>
    </collision>
    <inertial>
      <origin rpy="0 0 0" xyz="0 0 0"/>
      <mass value="2.0"/>
      <inertia ixx="0.0045" ixy="0" ixz="0" iyy="0.0045" iyz="0" izz="0.0045"/>
    </inertial>
  </link>
  <gazebo reference="right_wheel_link">
    <mu1>0.01</mu1>
    <mu2>0.01</mu2>
  </gazebo>
  <gazebo reference="right_wheel_link">
    <visual>
      <material>
        <ambient>0.1764 0.4588 0.8509 1.0</ambient>
        <diffuse>0.1764 0.4588 0.8509 1.0</diffuse>
        <specular>0.1764 0.4588 0.8509 1.0</specular>
        <emissive>0.0 0.0 0.0 0.0</emissive>
      </material>
    </visual>
  </gazebo>
  <joint name="right_wheel_joint" type="continuous">
    <axis xyz="0 1 0"/>
    <parent link="right_knee_link"/>
    <child link="right_wheel_link"/>
    <origin rpy="0 0 0" xyz="0.0 0.0 0.3"/>
    <dynamics damping="0.01" friction="0.0"/>
  </joint>
  <link name="left_passive_wheel_link">
    <visual>
      <origin rpy="1.5707963267948966 0 0" xyz="0 0 0"/>
      <geometry>
        <cylinder length="0.01" radius="0.03"/>
      </geometry>
      <material name="blue">
        <color rgba="0.1764 0.4588 0.8509 1.0"/>
      </material>
    </visual>
    <collision>
      <origin rpy="1.5707963267948966 0 0" xyz="0 0 0"/>
      <geometry>
        <cylinder length="0.01" radius="0.03"/>
      </geometry>
    </collision>
    <inertial>
      <origin rpy="0 0 0" xyz="0 0 0"/>
      <mass value="0.1"/>
      <inertia ixx="3.600000000000001e-05" ixy="0" ixz="0" iyy="3.600000000000001e-05" iyz="0" izz="3.600000000000001e-05"/>
    </inertial>
  </link>
  <gazebo reference="left_passive_wheel_link">
    <mu1>0.01</mu1>
    <mu2>0.01</mu2>
  </gazebo>
  <gazebo reference="left_passive_wheel_link">
    <visual>
      <material>
        <ambient>0.1764 0.4588 0.8509 1.0</ambient>
        <diffuse>0.1764 0.4588 0.8509 1.0</diffuse>
        <specular>0.1764 0.4588 0.8509 1.0</specular>
        <emissive>0.0 0.0 0.0 0.0</emissive>
      </material>
    </visual>
  </gazebo>
  <joint name="left_passive_wheel_joint" type="fixed">
    <axis xyz="0 0 0"/>
    <parent link="left_hip_link"/>
    <child link="left_passive_wheel_link"/>
    <origin rpy="0 0 0" xyz="0.0 0.0 0.34"/>
  </joint>
  <link name="right_passive_wheel_link">
    <visual>
      <origin rpy="1.5707963267948966 0 0" xyz="0 0 0"/>
      <geometry>
        <cylinder length="0.01" radius="0.03"/>
      </geometry>
      <material name="blue">
        <color rgba="0.1764 0.4588 0.8509 1.0"/>
      </material>
    </visual>
    <collision>
      <origin rpy="1.5707963267948966 0 0" xyz="0 0 0"/>
      <geometry>
        <cylinder length="0.01" radius="0.03"/>
      </geometry>
    </collision>
    <inertial>
      <origin rpy="0 0 0" xyz="0 0 0"/>
      <mass value="0.1"/>
      <inertia ixx="3.600000000000001e-05" ixy="0" ixz="0" iyy="3.600000000000001e-05" iyz="0" izz="3.600000000000001e-05"/>
    </inertial>
  </link>
  <gazebo reference="right_passive_wheel_link">
    <mu1>0.01</mu1>
    <mu2>0.01</mu2>
  </gazebo>
  <gazebo reference="right_passive_wheel_link">
    <visual>
      <material>
        <ambient>0.1764 0.4588 0.8509 1.0</ambient>
        <diffuse>0.1764 0.4588 0.8509 1.0</diffuse>
        <specular>0.1764 0.4588 0.8509 1.0</specular>
        <emissive>0.0 0.0 0.0 0.0</emissive>
      </material>
    </visual>
  </gazebo>
  <joint name="right_passive_wheel_joint" type="fixed">
    <axis xyz="0 0 0"/>
    <parent link="right_hip_link"/>
    <child link="right_passive_wheel_link"/>
    <origin rpy="0 0 0" xyz="0.0 0.0 0.34"/>
  </joint>
  <link name="camera_link">
    <visual>
      <origin rpy="0 0 0" xyz="0 0 0"/>
      <geometry>
        <box size="0.015 0.130 0.022"/>
      </geometry>
    </visual>
    <collision>
      <origin rpy="0 0 0" xyz="0 0 0"/>
      <geometry>
        <box size="0.015 0.130 0.022"/>
      </geometry>
    </collision>
    <inertial>
      <origin rpy="0 0 0" xyz="0 0 0"/>
      <mass value="0.035"/>
      <inertia ixx="0.001" ixy="0" ixz="0" iyy="0.001" iyz="0" izz="0.001"/>
    </inertial>
  </link>
  <joint name="camera_to_base_link" type="fixed">
    <parent link="base_link"/>
    <child link="camera_link"/>
    <origin rpy="0 0 0" xyz="0.2 0 0.2"/>
  </joint>
  <gazebo reference="camera_link">
    <sensor name="depth_camera" type="rgbd_camera">
      <always_on>true</always_on>
      <visualize>true</visualize>
      <update_rate>15</update_rate>
      <topic>depth_camera</topic>
      <gz_frame_id>camera_link</gz_frame_id>
      <camera>
        <horizontal_fov>1.047198</horizontal_fov>
        <image>
          <width>640</width>
          <height>480</height>
        </image>
        <clip>
          <near>0.05</near>
          <far>3.0</far>
        </clip>
        <distortion>
          <!-- Brown–Conrady -->
          <k1>0.0</k1>
          <k2>0.0</k2>
          <k3>0.0</k3>
          <p1>0.0</p1>
          <p2>0.0</p2>
          <center>0.5 0.5</center>
          <!-- principal point (normalized) -->
        </distortion>
      </camera>
    </sensor>
  </gazebo>
  <link name="imu_link">
    <visual>
      <origin rpy="0 0 0" xyz="0 0 0"/>
      <geometry>
        <box size="0.01 0.01 0.01"/>
      </geometry>
    </visual>
    <collision>
      <origin rpy="0 0 0" xyz="0 0 0"/>
      <geometry>
        <box size="0.01 0.01 0.01"/>
      </geometry>
    </collision>
    <inertial>
      <origin rpy="0 0 0" xyz="0 0 0"/>
      <mass value="0.035"/>
      <inertia ixx="0.001" ixy="0" ixz="0" iyy="0.001" iyz="0" izz="0.001"/>
    </inertial>
  </link>
  <joint name="imu_to_camera" type="fixed">
    <parent link="camera_link"/>
    <child link="imu_link"/>
    <origin rpy="0 0 0" xyz="0 0 0"/>
  </joint>
  <gazebo reference="imu_link">
    <sensor name="imu_sensor" type="imu">
      <pose relative_to="base_link">0 0 0 0 0 0</pose>
      <always_on>1</always_on>
      <update_rate>1000.0</update_rate>
      <topic>imu</topic>
      <gz_frame_id>imu_link</gz_frame_id>
    </sensor>
    <sensor name="navsat" type="navsat">
      <always_on>1</always_on>
      <update_rate>1</update_rate>
      <topic>navsat</topic>
      <gz_frame_id>imu_link</gz_frame_id>
    </sensor>
  </gazebo>
  <!-- <xacro:ambula_ros2_control/> -->
</robot>
