<?xml version="1.0"?>
<robot xmlns:xacro="http://www.ros.org/wiki/xacro">

    <link name="camera_link">
        <visual>
            <origin xyz="0 0 0" rpy="0 0 0"/>
            <geometry>
                <box size="0.015 0.130 0.022"/>
            </geometry>
        </visual>

        <collision>
            <origin xyz="0 0 0" rpy="0 0 0"/>
            <geometry>
                <box size="0.015 0.130 0.022"/>
            </geometry>
        </collision>

        <inertial>
            <origin xyz="0 0 0" rpy="0 0 0"/>
            <mass value="0.035"/>
            <inertia ixx="0.001" ixy="0" ixz="0" iyy="0.001" iyz="0" izz="0.001" />
        </inertial>
    </link>

    <joint name="slider_to_camera" type="prismatic">
        <axis xyz="0 0 1" />
        <origin xyz="0.0 0.0 0.0" />
        <parent link="base_link" />
        <child link="camera_link" />
        <limit effort="100" lower="0.0" upper="2.5" velocity="10" />
        <dynamics damping="0.2" />
    </joint>

    <gazebo reference="camera_link">
        <sensor name="depth_camera" type="rgbd_camera">
            <always_on>true</always_on>
            <visualize>true</visualize>
            <update_rate>5.0</update_rate>
            <topic>depth_camera</topic>
            <gz_frame_id>camera_link</gz_frame_id>
            <camera>
                <horizontal_fov>1.047198</horizontal_fov>
                <image>
                    <width>640</width>
                    <height>480</height>
                </image>
                <clip>
                    <near>0.05</near>
                    <far>3</far>
                </clip>
            </camera>
            <baseline>0.2</baseline>
            <pointCloudCutoff>0.5</pointCloudCutoff>
            <pointCloudCutoffMax>3.0</pointCloudCutoffMax>
            <distortionK1>0</distortionK1>
            <distortionK2>0</distortionK2>
            <distortionK3>0</distortionK3>
            <distortionT1>0</distortionT1>
            <distortionT2>0</distortionT2>
            <CxPrime>0</CxPrime>
            <Cx>0</Cx>
            <Cy>0</Cy>
            <focalLength>0</focalLength>
            <hackBaseline>0</hackBaseline>
        </sensor>
        <sensor name="front_cam" type="camera">
            <gz_frame_id>camera_link</gz_frame_id>
            <camera>
                <horizontal_fov>1.047</horizontal_fov>
                <image>
                    <width>1920</width>
                    <height>1080</height>
                </image>
                <clip>
                    <near>0.1</near>
                    <far>100</far>
                </clip>
            </camera>
            <always_on>1</always_on>
            <update_rate>30</update_rate>
            <visualize>true</visualize>
            <topic>fwd_cam</topic>
        </sensor>
    </gazebo>

</robot>
