<?xml version="1.0" ?>
<!-- =================================================================================== -->
<!-- |    This document was autogenerated by xacro from ambula.urdf.xacro              | -->
<!-- |    EDITING THIS FILE BY HAND IS NOT RECOMMENDED                                 | -->
<!-- =================================================================================== -->
<robot name="ambula_bot">
  <!-- <link name="world" /> -->
  <link name="base_footprint"/>
  <link name="base_link">
    <visual>
      <origin rpy="-1.5707963267948966 0 0" xyz="0 0 0"/>
      <geometry>
        <mesh filename="package://ambula_description/meshs/base.stl" scale="1 1 1"/>
      </geometry>
      <material name="black">
        <color rgba="0.0 0.0 0.0 1.0"/>
      </material>
    </visual>
    <collision>
      <origin rpy="-1.5707963267948966 0 0" xyz="0 0 0"/>
      <geometry>
        <mesh filename="package://ambula_description/meshs/base.stl" scale="1 1 1"/>
      </geometry>
    </collision>
    <inertial>
      <origin rpy="0 0 0" xyz="0 0 -0.07"/>
      <mass value="7.0"/>
      <inertia ixx="0.08219166666666668" ixy="0.0" ixz="0.0" iyy="0.12559166666666666" iyz="0.0" izz="0.11631666666666665"/>
    </inertial>
  </link>
  <gazebo reference="base_link">
    <visual>
      <material>
        <ambient>0.8392 0.6314 0.0 1.0</ambient>
        <diffuse>0.8392 0.6314 0.0 1.0</diffuse>
        <specular>0.99 0.99 0.99 1.0</specular>
        <emissive>0.0 0.0 0.0 0.0</emissive>
      </material>
    </visual>
  </gazebo>
  <joint name="base_to_footprint" type="fixed">
    <parent link="base_footprint"/>
    <child link="base_link"/>
    <origin rpy="0 0 0" xyz="0 0 0.5"/>
  </joint>
  <link name="left_waist_link">
    <visual>
      <origin rpy="-1.5707963267948966 0 0" xyz="0 0 0"/>
      <geometry>
        <mesh filename="package://ambula_description/meshs/left_waist.stl" scale="1 1 1"/>
      </geometry>
      <material name="orange">
        <color rgba="0.8 0.15 0.0 1.0"/>
      </material>
    </visual>
    <collision>
      <origin rpy="-1.5707963267948966 0 0" xyz="0 0 0"/>
      <geometry>
        <mesh filename="package://ambula_description/meshs/left_waist.stl" scale="1 1 1"/>
      </geometry>
    </collision>
    <inertial>
      <origin rpy="0 0 0" xyz="0 0 0"/>
      <mass value="1.0"/>
      <inertia ixx="0.001666666666666667" ixy="0.0" ixz="0.0" iyy="0.002241666666666667" iyz="0.0" izz="0.002241666666666667"/>
    </inertial>
  </link>
  <joint name="left_waist_joint" type="revolute">
    <axis xyz="1 0 0"/>
    <origin xyz="-0.05 0.0875 -0.1165"/>
    <parent link="base_link"/>
    <child link="left_waist_link"/>
    <limit effort="1000" lower="-0.7853981633974483" upper="0.7853981633974483" velocity="10"/>
    <dynamics damping="5.0" friction="3.0"/>
  </joint>
  <link name="right_waist_link">
    <visual>
      <origin rpy="-1.5707963267948966 0 0" xyz="0 0 0"/>
      <geometry>
        <mesh filename="package://ambula_description/meshs/right_waist.stl" scale="1 1 1"/>
      </geometry>
      <material name="orange">
        <color rgba="0.8 0.15 0.0 1.0"/>
      </material>
    </visual>
    <collision>
      <origin rpy="-1.5707963267948966 0 0" xyz="0 0 0"/>
      <geometry>
        <mesh filename="package://ambula_description/meshs/right_waist.stl" scale="1 1 1"/>
      </geometry>
    </collision>
    <inertial>
      <origin rpy="0 0 0" xyz="0 0 0"/>
      <mass value="1.0"/>
      <inertia ixx="0.001666666666666667" ixy="0.0" ixz="0.0" iyy="0.002241666666666667" iyz="0.0" izz="0.002241666666666667"/>
    </inertial>
  </link>
  <joint name="right_waist_joint" type="revolute">
    <axis xyz="1 0 0"/>
    <origin xyz="-0.05 -0.0875 -0.1165"/>
    <parent link="base_link"/>
    <child link="right_waist_link"/>
    <limit effort="1000" lower="-0.7853981633974483" upper="0.7853981633974483" velocity="10"/>
    <dynamics damping="5.0" friction="3.0"/>
  </joint>
  <link name="left_hip_link">
    <visual>
      <origin rpy="-1.5707963267948966 0 0" xyz="0 0 0"/>
      <geometry>
        <mesh filename="package://ambula_description/meshs/left_hip.stl" scale="1 1 1"/>
      </geometry>
      <material name="orange">
        <color rgba="0.8 0.15 0.0 1.0"/>
      </material>
    </visual>
    <collision>
      <origin rpy="-1.5707963267948966 0 0" xyz="0 0 0"/>
      <geometry>
        <mesh filename="package://ambula_description/meshs/left_hip.stl" scale="1 1 1"/>
      </geometry>
    </collision>
    <inertial>
      <origin rpy="0 0 0" xyz="0 0 0.11560000000000002"/>
      <mass value="1.0"/>
      <inertia ixx="0.009933333333333336" ixy="0.0" ixz="0.0" iyy="0.010466666666666668" iyz="0.0" izz="0.0011333333333333334"/>
    </inertial>
  </link>
  <joint name="left_hip_joint" type="revolute">
    <axis xyz="0 -1 0"/>
    <origin xyz="0.0 0.055 0.0"/>
    <parent link="left_waist_link"/>
    <child link="left_hip_link"/>
    <limit effort="1000" lower="0.9599310885968811" upper="3.141592653589793" velocity="10"/>
    <dynamics damping="5.0" friction="3.0"/>
  </joint>
  <link name="right_hip_link">
    <visual>
      <origin rpy="-1.5707963267948966 0 0" xyz="0 0 0"/>
      <geometry>
        <mesh filename="package://ambula_description/meshs/right_hip.stl" scale="1 1 1"/>
      </geometry>
      <material name="orange">
        <color rgba="0.8 0.15 0.0 1.0"/>
      </material>
    </visual>
    <collision>
      <origin rpy="-1.5707963267948966 0 0" xyz="0 0 0"/>
      <geometry>
        <mesh filename="package://ambula_description/meshs/right_hip.stl" scale="1 1 1"/>
      </geometry>
    </collision>
    <inertial>
      <origin rpy="0 0 0" xyz="0 0 0.11560000000000002"/>
      <mass value="1.0"/>
      <inertia ixx="0.009933333333333336" ixy="0.0" ixz="0.0" iyy="0.010466666666666668" iyz="0.0" izz="0.0011333333333333334"/>
    </inertial>
  </link>
  <joint name="right_hip_joint" type="revolute">
    <axis xyz="0 -1 0"/>
    <origin xyz="0.0 -0.055 0.0"/>
    <parent link="right_waist_link"/>
    <child link="right_hip_link"/>
    <limit effort="1000" lower="0.9599310885968811" upper="3.141592653589793" velocity="10"/>
    <dynamics damping="5.0" friction="3.0"/>
  </joint>
  <link name="left_knee_link">
    <visual>
      <origin rpy="-1.5707963267948966 0 0" xyz="0 0 0"/>
      <geometry>
        <mesh filename="package://ambula_description/meshs/left_knee.stl" scale="1 1 1"/>
      </geometry>
      <material name="black">
        <color rgba="0.0 0.0 0.0 1.0"/>
      </material>
    </visual>
    <collision>
      <origin rpy="-1.5707963267948966 0 0" xyz="0 0 0"/>
      <geometry>
        <mesh filename="package://ambula_description/meshs/left_knee.stl" scale="1 1 1"/>
      </geometry>
    </collision>
    <inertial>
      <origin rpy="0 0 0" xyz="0 0 0.10640000000000001"/>
      <mass value="0.5"/>
      <inertia ixx="0.0035333333333333336" ixy="0.0" ixz="0.0" iyy="0.0033708333333333338" iyz="0.0" izz="0.00037083333333333337"/>
    </inertial>
  </link>
  <joint name="left_knee_joint" type="revolute">
    <axis xyz="0 -1 0"/>
    <origin xyz="-0.015 0.0 0.201"/>
    <parent link="left_hip_link"/>
    <child link="left_knee_link"/>
    <limit effort="1000" lower="1.2217304763960306" upper="2.530727415391778" velocity="10"/>
    <dynamics damping="5.0" friction="3.0"/>
  </joint>
  <link name="right_knee_link">
    <visual>
      <origin rpy="-1.5707963267948966 0 0" xyz="0 0 0"/>
      <geometry>
        <mesh filename="package://ambula_description/meshs/right_knee.stl" scale="1 1 1"/>
      </geometry>
      <material name="black">
        <color rgba="0.0 0.0 0.0 1.0"/>
      </material>
    </visual>
    <collision>
      <origin rpy="-1.5707963267948966 0 0" xyz="0 0 0"/>
      <geometry>
        <mesh filename="package://ambula_description/meshs/right_knee.stl" scale="1 1 1"/>
      </geometry>
    </collision>
    <inertial>
      <origin rpy="0 0 0" xyz="0 0 0.10640000000000001"/>
      <mass value="0.5"/>
      <inertia ixx="0.0035333333333333336" ixy="0.0" ixz="0.0" iyy="0.0033708333333333338" iyz="0.0" izz="0.00037083333333333337"/>
    </inertial>
  </link>
  <joint name="right_knee_joint" type="revolute">
    <axis xyz="0 -1 0"/>
    <origin xyz="-0.015 0.0 0.201"/>
    <parent link="right_hip_link"/>
    <child link="right_knee_link"/>
    <limit effort="1000" lower="1.2217304763960306" upper="2.530727415391778" velocity="10"/>
    <dynamics damping="5.0" friction="3.0"/>
  </joint>
  <link name="left_wheel_link">
    <visual>
      <origin rpy="-1.5707963267948966 0 0" xyz="0 0 0"/>
      <geometry>
        <mesh filename="package://ambula_description/meshs/wheel.stl" scale="1 1 1"/>
      </geometry>
      <material name="black">
        <color rgba="0.0 0.0 0.0 1.0"/>
      </material>
    </visual>
    <collision>
      <origin rpy="-1.5707963267948966 0 0" xyz="0 0 0"/>
      <geometry>
        <mesh filename="package://ambula_description/meshs/wheel.stl" scale="1 1 1"/>
      </geometry>
    </collision>
    <inertial>
      <origin rpy="0 0 0" xyz="0 0 0"/>
      <mass value="1.6"/>
      <inertia ixx="0.002293333333333334" ixy="0" ixz="0" iyy="0.003920000000000001" iyz="0" izz="0.002293333333333334"/>
    </inertial>
  </link>
  <joint name="left_wheel_joint" type="continuous">
    <axis xyz="0 1 0"/>
    <parent link="left_knee_link"/>
    <child link="left_wheel_link"/>
    <origin rpy="0 0 0" xyz="0.0 0.0 0.235"/>
    <dynamics damping="0.01" friction="0.0"/>
  </joint>
  <link name="right_wheel_link">
    <visual>
      <origin rpy="-1.5707963267948966 0 0" xyz="0 0 0"/>
      <geometry>
        <mesh filename="package://ambula_description/meshs/wheel.stl" scale="1 1 1"/>
      </geometry>
      <material name="black">
        <color rgba="0.0 0.0 0.0 1.0"/>
      </material>
    </visual>
    <collision>
      <origin rpy="-1.5707963267948966 0 0" xyz="0 0 0"/>
      <geometry>
        <mesh filename="package://ambula_description/meshs/wheel.stl" scale="1 1 1"/>
      </geometry>
    </collision>
    <inertial>
      <origin rpy="0 0 0" xyz="0 0 0"/>
      <mass value="1.6"/>
      <inertia ixx="0.002293333333333334" ixy="0" ixz="0" iyy="0.003920000000000001" iyz="0" izz="0.002293333333333334"/>
    </inertial>
  </link>
  <joint name="right_wheel_joint" type="continuous">
    <axis xyz="0 1 0"/>
    <parent link="right_knee_link"/>
    <child link="right_wheel_link"/>
    <origin rpy="0 0 0" xyz="0.0 0.0 0.235"/>
    <dynamics damping="0.01" friction="0.0"/>
  </joint>
  <link name="camera_link">
    <visual>
      <origin rpy="0 0 0" xyz="0 0 0"/>
      <geometry>
        <box size="0.015 0.130 0.022"/>
      </geometry>
    </visual>
    <collision>
      <origin rpy="0 0 0" xyz="0 0 0"/>
      <geometry>
        <box size="0.015 0.130 0.022"/>
      </geometry>
    </collision>
    <inertial>
      <origin rpy="0 0 0" xyz="0 0 0"/>
      <mass value="0.035"/>
      <inertia ixx="0.001" ixy="0" ixz="0" iyy="0.001" iyz="0" izz="0.001"/>
    </inertial>
  </link>
  <joint name="camera_to_base_link" type="fixed">
    <parent link="base_link"/>
    <child link="camera_link"/>
    <origin rpy="0 0 0" xyz="0.11 0 -0.055"/>
  </joint>
  <gazebo reference="camera_link">
    <sensor name="depth_camera" type="rgbd_camera">
      <always_on>true</always_on>
      <visualize>true</visualize>
      <update_rate>15</update_rate>
      <topic>depth_camera</topic>
      <gz_frame_id>camera_link</gz_frame_id>
      <camera>
        <horizontal_fov>1.047198</horizontal_fov>
        <image>
          <width>640</width>
          <height>480</height>
        </image>
        <clip>
          <near>0.05</near>
          <far>3.0</far>
        </clip>
        <distortion>
          <!-- Brown–Conrady -->
          <k1>0.0</k1>
          <k2>0.0</k2>
          <k3>0.0</k3>
          <p1>0.0</p1>
          <p2>0.0</p2>
          <center>0.5 0.5</center>
          <!-- principal point (normalized) -->
        </distortion>
      </camera>
    </sensor>
  </gazebo>
  <link name="imu_base_link">
    <visual>
      <origin rpy="0 0 0" xyz="0 0 0"/>
      <geometry>
        <box size="0.01 0.01 0.01"/>
      </geometry>
    </visual>
    <collision>
      <origin rpy="0 0 0" xyz="0 0 0"/>
      <geometry>
        <box size="0.01 0.01 0.01"/>
      </geometry>
    </collision>
    <inertial>
      <origin rpy="0 0 0" xyz="0 0 0"/>
      <mass value="0.035"/>
      <inertia ixx="0.001" ixy="0" ixz="0" iyy="0.001" iyz="0" izz="0.001"/>
    </inertial>
  </link>
  <joint name="imu_to_base" type="fixed">
    <parent link="base_link"/>
    <child link="imu_base_link"/>
    <origin rpy="0 0 0" xyz="0 0 0"/>
  </joint>
  <gazebo reference="imu_base_link">
    <sensor name="imu_sensor" type="imu">
      <pose relative_to="base_link">0 0 0 0 0 0</pose>
      <always_on>1</always_on>
      <update_rate>1000.0</update_rate>
      <topic>imu</topic>
      <gz_frame_id>imu_base_link</gz_frame_id>
    </sensor>
    <sensor name="navsat" type="navsat">
      <always_on>1</always_on>
      <update_rate>1</update_rate>
      <topic>navsat</topic>
      <gz_frame_id>imu_base_link</gz_frame_id>
    </sensor>
  </gazebo>
  <link name="imu_cam_link">
    <visual>
      <origin rpy="0 0 0" xyz="0 0 0"/>
      <geometry>
        <box size="0.01 0.01 0.01"/>
      </geometry>
    </visual>
    <collision>
      <origin rpy="0 0 0" xyz="0 0 0"/>
      <geometry>
        <box size="0.01 0.01 0.01"/>
      </geometry>
    </collision>
    <inertial>
      <origin rpy="0 0 0" xyz="0 0 0"/>
      <mass value="0.035"/>
      <inertia ixx="0.001" ixy="0" ixz="0" iyy="0.001" iyz="0" izz="0.001"/>
    </inertial>
  </link>
  <joint name="imu_to_camera" type="fixed">
    <parent link="camera_link"/>
    <child link="imu_cam_link"/>
    <origin rpy="0 0 0" xyz="0 0 0"/>
  </joint>
  <gazebo reference="imu_cam_link">
    <sensor name="imu_sensor" type="imu">
      <pose relative_to="base_link">0 0 0 0 0 0</pose>
      <always_on>1</always_on>
      <update_rate>1000.0</update_rate>
      <topic>imu</topic>
      <gz_frame_id>imu_cam_link</gz_frame_id>
    </sensor>
    <sensor name="navsat" type="navsat">
      <always_on>1</always_on>
      <update_rate>1</update_rate>
      <topic>navsat</topic>
      <gz_frame_id>imu_cam_link</gz_frame_id>
    </sensor>
  </gazebo>
  <!-- <xacro:ambula_ros2_control/> -->
</robot>
