<?xml version="1.0"?>
<robot xmlns:xacro="http://www.ros.org/wiki/xacro">

    <link name="camera_link">
        <visual>
            <origin xyz="0 0 0" rpy="0 0 0"/>
            <geometry>
                <box size="0.015 0.130 0.022"/>
            </geometry>
        </visual>

        <collision>
            <origin xyz="0 0 0" rpy="0 0 0"/>
            <geometry>
                <box size="0.015 0.130 0.022"/>
            </geometry>
        </collision>

        <inertial>
            <origin xyz="0 0 0" rpy="0 0 0"/>
            <mass value="0.035"/>
            <inertia ixx="0.001" ixy="0" ixz="0" iyy="0.001" iyz="0" izz="0.001" />
        </inertial>
    </link>

    <joint name="slider_to_camera" type="prismatic">
        <axis xyz="0 0 1" />
        <origin xyz="0.0 0.0 0.0" />
        <parent link="base_link" />
        <child link="camera_link" />
        <limit effort="100" lower="0.0" upper="2.5" velocity="10" />
        <dynamics damping="0.2" />
    </joint>

    <gazebo reference="camera_link">
        <sensor name="depth_camera" type="rgbd_camera">
            <always_on>true</always_on>
            <visualize>true</visualize>
            <update_rate>15</update_rate>
            <topic>depth_camera</topic>
            <gz_frame_id>camera_link</gz_frame_id>
            <camera>
                <horizontal_fov>1.047198</horizontal_fov>
                <image>
                    <width>640</width>
                    <height>480</height>
                </image>
                <clip>
                    <near>0.05</near>
                    <far>3.0</far>
                </clip>
                <distortion>                 <!-- Brown–Conrady -->
                    <k1>0.0</k1>
                    <k2>0.0</k2>
                    <k3>0.0</k3>
                    <p1>0.0</p1>
                    <p2>0.0</p2>
                    <center>0.5 0.5</center>  <!-- principal point (normalized) -->
                </distortion>
            </camera>
        </sensor>
    </gazebo>

</robot>
