<?xml version="1.0" ?>
<!-- =================================================================================== -->
<!-- |    This document was autogenerated by xacro from Base.xacro                     | -->
<!-- |    EDITING THIS FILE BY HAND IS NOT RECOMMENDED                                 | -->
<!-- =================================================================================== -->
<robot name="ambula_bot">
  <material name="orange">
    <color rgba="0.8 0.15 0.0 1.0"/>
  </material>
  <material name="black">
    <color rgba="0.0 0.0 0.0 1.0"/>
  </material>
  <!-- <xacro:include filename="$(find Base_description)/urdf/Base.trans" /> -->
  <!-- <xacro:include filename="$(find Base_description)/urdf/Base.gazebo" /> -->
  <link name="base_rotated">
    <inertial>
      <origin xyz="0 0 0" rpy="0 0 0"/>
      <mass value="0.0001"/>
      <inertia ixx="1e-6" ixy="0" ixz="0" iyy="1e-6" iyz="0" izz="1e-6"/>
    </inertial>
    <collision>
      <origin xyz="0 0 0" rpy="0 0 0"/>
      <geometry>
        <box size="0.001 0.001 0.001"/>
      </geometry>
    </collision>
  </link>
  <link name="base_link">
    <inertial>
      <origin rpy="0 0 0" xyz="0 0.03 0.0"/>
      <mass value="7.5"/>
      <inertia ixx="0.05" ixy="0.0" ixz="0.0" iyy="0.08" iyz="0.0" izz="0.09"/>
    </inertial>
    <visual>
      <origin rpy="0 0 0" xyz="0 0 0"/>
      <geometry>
        <mesh filename="package://Base_description/meshes/base_link_2.stl" scale="1 1 1"/>
      </geometry>
      <material name="black"/>
    </visual>
    <collision>
      <origin rpy="0 0 0" xyz="0 0 0"/>
      <geometry>
        <mesh filename="package://Base_description/meshes/base_link_2.stl" scale="1 1 1"/>
      </geometry>
    </collision>
  </link>
  <link name="right_hip_link">
    <inertial>
      <origin rpy="0 0 0" xyz="0 0 0"/>
      <mass value="1.0"/>
      <inertia ixx="0.0012" ixy="0.0" ixz="0.0" iyy="0.0012" iyz="0.0" izz="0.0012"/>
    </inertial>
    <visual>
      <origin rpy="0 0 0" xyz="0 0 0"/>
      <geometry>
        <mesh filename="package://Base_description/meshes/right_hip_link_2.stl" scale="1 1 1"/>
      </geometry>
      <material name="orange"/>
    </visual>
    <collision>
      <origin rpy="0 0 0" xyz="0 0 0"/>
      <geometry>
        <mesh filename="package://Base_description/meshes/right_hip_link_2.stl" scale="1 1 1"/>
      </geometry>
    </collision>
  </link>
  <link name="left_hip_link">
    <inertial>
      <origin rpy="0 0 0" xyz="0 0 0"/>
      <mass value="1.0"/>
      <inertia ixx="0.0012" ixy="0.0" ixz="0.0" iyy="0.0012" iyz="0.0" izz="0.0012"/>
    </inertial>
    <visual>
      <origin rpy="0 0 0" xyz="0 0 0"/>
      <geometry>
        <mesh filename="package://Base_description/meshes/left_hip_link_2.stl" scale="1 1 1"/>
      </geometry>
      <material name="orange"/>
    </visual>
    <collision>
      <origin rpy="0 0 0" xyz="0 0 0"/>
      <geometry>
        <mesh filename="package://Base_description/meshes/left_hip_link_2.stl" scale="1 1 1"/>
      </geometry>
    </collision>
  </link>
  <link name="right_knee_link">
    <inertial>
      <origin rpy="0 0 0" xyz="0 0 0"/>
      <mass value="1.0"/>
      <inertia ixx="0.0012" ixy="0.0" ixz="0.0" iyy="0.0012" iyz="0.0" izz="0.0012"/>
    </inertial>
    <visual>
      <origin rpy="0 0 0" xyz="0 0 0"/>
      <geometry>
        <mesh filename="package://Base_description/meshes/right_knee_link_2.stl" scale="1 1 1"/>
      </geometry>
      <material name="black"/>
    </visual>
    <collision>
      <origin rpy="0 0 0" xyz="0 0 0"/>
      <geometry>
        <mesh filename="package://Base_description/meshes/right_knee_link_2.stl" scale="1 1 1"/>
      </geometry>
    </collision>
  </link>
  <link name="left_knee_link">
    <inertial>
      <origin rpy="0 0 0" xyz="0 0 0"/>
      <mass value="1.0"/>
      <inertia ixx="0.0012" ixy="0.0" ixz="0.0" iyy="0.0012" iyz="0.0" izz="0.0012"/>
    </inertial>
    <visual>
      <origin rpy="0 0 0" xyz="0 0 0"/>
      <geometry>
        <mesh filename="package://Base_description/meshes/left_knee_link_2.stl" scale="1 1 1"/>
      </geometry>
      <material name="black"/>
    </visual>
    <collision>
      <origin rpy="0 0 0" xyz="0 0 0"/>
      <geometry>
        <mesh filename="package://Base_description/meshes/left_knee_link_2.stl" scale="1 1 1"/>
      </geometry>
    </collision>
  </link>
  <link name="right_wheel_link">
    <inertial>
      <origin rpy="0 0 0" xyz="0 0 0"/>
      <mass value="1.6"/>
      <inertia ixx="0.003364" ixy="0.0" ixz="1.45e-06" iyy="0.002031" iyz="0.0" izz="0.002031"/>
    </inertial>
    <visual>
      <origin rpy="0 0 0" xyz="0 0 0"/>
      <geometry>
        <mesh filename="package://Base_description/meshes/right_wheel_link_2.stl" scale="1 1 1"/>
      </geometry>
      <material name="black"/>
    </visual>
    <collision>
      <origin rpy="0 0 0" xyz="0 0 0"/>
      <geometry>
        <mesh filename="package://Base_description/meshes/right_wheel_link_2.stl" scale="1 1 1"/>
      </geometry>
    </collision>
  </link>
  <link name="left_wheel_link">
    <inertial>
      <origin rpy="0 0 0" xyz="0 0 0"/>
      <mass value="1.6"/>
      <inertia ixx="0.003364" ixy="0.0" ixz="-1.45e-06" iyy="0.002031" iyz="0.0" izz="0.002031"/>
    </inertial>
    <visual>
      <origin rpy="0 0 0" xyz="0 0 0"/>
      <geometry>
        <mesh filename="package://Base_description/meshes/left_wheel_link_2.stl" scale="1 1 1"/>
      </geometry>
      <material name="black"/>
    </visual>
    <collision>
      <origin rpy="0 0 0" xyz="0 0 0"/>
      <geometry>
        <mesh filename="package://Base_description/meshes/left_wheel_link_2.stl" scale="1 1 1"/>
      </geometry>
    </collision>
  </link>
  <link name="Component2_1_1">
    <inertial>
      <origin rpy="0 0 0" xyz="0 0 0"/>
      <mass value="0.3"/>
      <inertia ixx="0.000151" ixy="0.0" ixz="0.0" iyy="0.001191" iyz="-0.0000384" izz="0.001199"/>
    </inertial>
    <visual>
      <origin rpy="0 0 0" xyz="0 0 0"/>
      <geometry>
        <mesh filename="package://Base_description/meshes/Component2_1_2.stl" scale="1 1 1"/>
      </geometry>
      <material name="black"/>
    </visual>
    <collision>
      <origin rpy="0 0 0" xyz="0 0 0"/>
      <geometry>
        <mesh filename="package://Base_description/meshes/Component2_1_2.stl" scale="1 1 1"/>
      </geometry>
    </collision>
  </link>
  <joint name="right_hip_joint" type="revolute">
    <origin rpy="0 0 0" xyz="0.190131 -0.032582 -0.07"/>
    <parent link="base_link"/>
    <child link="right_hip_link"/>
    <axis xyz="1 0 0"/>
    <limit lower="0.5236" upper="2.5307" effort="150" velocity="6.0"/>
  </joint>
  <joint name="left_hip_joint" type="revolute">
    <origin rpy="0 0 0" xyz="-0.190131 -0.032582 -0.07"/>
    <parent link="base_link"/>
    <child link="left_hip_link"/>
    <axis xyz="1 0 0"/>
    <limit lower="0.5236" upper="2.5307" effort="150" velocity="6.0"/>
  </joint>
  <joint name="right_knee_joint" type="revolute">
    <origin rpy="0 0 0" xyz="-0.0485 -0.118102 0.162133"/>
    <parent link="right_hip_link"/>
    <child link="right_knee_link"/>
    <axis xyz="1 0 0"/>
    <limit lower="-0.1745" upper="0.7854" effort="150" velocity="6.0"/>
  </joint>
  <joint name="left_knee_joint" type="revolute">
    <origin rpy="0 0 0" xyz="0.0485 -0.118102 0.162133"/>
    <parent link="left_hip_link"/>
    <child link="left_knee_link"/>
    <axis xyz="1 0 0"/>
    <limit lower="-0.1745" upper="0.7854" effort="150" velocity="6.0"/>
  </joint>
  <joint name="right_wheel_joint" type="revolute">
    <origin rpy="0 0 0" xyz="0.0 -0.177143 -0.156455"/>
    <parent link="right_knee_link"/>
    <child link="right_wheel_link"/>
    <axis xyz="1 0 0"/>
  </joint>
  <joint name="left_wheel_joint" type="continuous">
    <origin rpy="0 0 0" xyz="-0.0 -0.177143 -0.156455"/>
    <parent link="left_knee_link"/>
    <child link="left_wheel_link"/>
    <axis xyz="1 0 0"/>
  </joint>
  <joint name="body_joint" type="fixed">
    <origin rpy="0 0 0" xyz="-0.001 -0.1425  -0.025"/>
    <parent link="base_link"/>
    <child link="Component2_1_1"/>
  </joint>
  <joint name="base_rotation_joint" type="fixed">
    <!-- roll pitch yaw -->
    <origin rpy="0 0 -1.57079632679" xyz="0 0 0"/>
    <parent link="base_rotated"/>
    <child link="base_link"/>
  </joint>
</robot>
